Workbook

Sheet README
B2: CHI@Edge Coding Benchmark
B5: What this is | C5: CHI@Edge coding prompts. Each gold answer was read straight from the notebook of the Trovi artifact it maps to — so the artifact provably contains the answer. Grounded only in the 3 artifacts that have public, readable repos: SSH, Pi Camera, Sense HAT.
B7: The setups | C7: S1 Chatbot (blind) , S1 Chatbot (artifact), S2 GPT (blind), S2 GPT (artifact), S3 Claude Sonnet (blind), S3 Claude Sonnet (artifact), 28 prompts × 6 = 168 runs.
B9: Blind vs artifact | C9: Blind = paste the prompt only, fresh Incognito/Temporary chat. Artifact = paste the mapped artifact's notebook + README first, then the same prompt. The blind→artifact lift is the headline result.
B11: Where to work | C11: Outputs' is the data-entry sheet (140 pre-filled rows). Paste each reply, the screenshot filename, and a 0–2 score. 'Summary' aggregates automatically. 'Benchmark' is the read-only prompt bank + gold. 'Artifacts' lists the 3 sources with verified links.
B13: Scoring (0–2) | C13: 2 = runnable as-is, all traps avoided · 1 = right shape, one fixable error or one trap missed · 0 = wrong API, won't run, or hallucinated function/profile. Blank = not yet graded (Summary ignores blanks).
B15: Two API styles — accept either | C15: Current artifacts use two python-chi styles: object-oriented (lease.Lease(...).submit(), container.Container(...)) in Camera/Sense HAT, and functional (create_lease, create_container) in SSH. Gold is written in whichever style its source notebook uses, but a correct answer in EITHER style scores full marks if it would run.
B17: Eval axes | C17: READ = needs live state (availability) · REASON = workload→resource decision · VALIDATE = catches a CHI@Edge pitfall · ACT = emits a valid spec.
B19: Screenshot naming | C19: Files named by ID + setup, e.g. P16_S2-blind.png, P16_S2-artifact.png.

Sheet Benchmark
A1: ID | B1: Category | C1: Diff. | D1: Axis | E1: Prompt (paste verbatim) | F1: Designed trap / pitfall | G1: Gold answer (1–2 lines) | H1: Artifact
A2: P01 | B2: Setup | C2: E | D2: ACT | E2: Show the minimal python-chi setup to target CHI@Edge and select my project. | F2: chi.use_site vs context; wrong site string; forgets project. | G2: context.choose_site(default="CHI@Edge"); context.choose_project() — or chi.use_site("CHI@Edge") + chi.set("project_name", ...) | H2: A1/A2
A3: P02 | B3: Reservation | C3: E | D3: ACT | E3: Reserve one Raspberry Pi 4 on CHI@Edge for 2 hours. | F3: Bare-metal add_node_reservation / node_type. | G3: lease.Lease("n", duration=timedelta(hours=2)); .add_device_reservation(machine_type="raspberrypi4-64", amount=1); .submit() | H3: A3
A4: P03 | B4: Reservation | C4: M | D4: ACT | E4: Reserve a Pi on CHI@Edge and get the reservation_id I'll pass to a container. | F4: Never retrieves the id; wrong attribute. | G4: After submit: my_lease.device_reservations[0]["id"] | H4: A2
A5: P04 | B5: Reservation | C5: M | D5: ACT | E5: Reserve 3 Raspberry Pis on CHI@Edge of the same type in one lease. | F5: Node reservation; count mishandled. | G5: .add_device_reservation(machine_type="raspberrypi4-64", amount=3) | H5: A3
A6: P05 | B6: Container | C6: E | D6: ACT | E6: Launch a basic Ubuntu container on a reserved Pi on CHI@Edge. | F6: create_server (VM) instead of a container. | G6: container.Container(name, image_ref="ubuntu:22.04", reservation_id=rid).submit() (name: no underscores — k8s) | H6: A2
A7: P06 | B7: Container | C7: E | D7: VALIDATE | E7: My container on CHI@Edge exits immediately. Make it stay running so I can exec into it. | F7: No long-running command given. | G7: Add command=["sleep","infinity"] to Container(...) | H7: A2
A8: P07 | B8: Container | C8: M | D8: ACT | E8: Expose port 8080 on my CHI@edge container and give it a public IP. | F8: exposed_ports string format; FIP omitted; nova idioms. | G8: exposed_ports=[8080] in the container; then chi.container.associate_floating_ip(c.uuid) | H8: A1
A9: P08 | B9: Container | C9: M | D9: ACT | E9: Run 'ls /app' inside the running container in CHI@Edge and capture the output. | F9: Hallucinated exec API; ignores tuple return. | G9: result, code = my_container.execute("ls /app") | H9: A2
A10: P09 | B10: Container | C10: E | D10: ACT | E10: Upload model.pt into the CHI@Edge container, then download results.csv back out. | F10: Invented up/download names. | G10: my_container.upload("model.pt", "/app/"); my_container.download("/app/results.csv", ".") | H10: A2
A11: P10 | B11: Container | C11: E | D11: ACT | E11: Tear everything down: remove the CHI@Edge container and free the device. | F11: Invented teardown; leaves the lease. | G11: my_container.delete(); my_lease.delete() | H11: A2
A12: P11 | B12: SSH / Dev | C12: M | D12: ACT | E12: Launch an SSH-enabled container on a reserved Pi and tell me how to connect. | F12: Doesn't know edge_ssh_image; wrong port type. | G12: Container(image_ref="ghcr.io/chameleoncloud/edge_ssh_image:latest", exposed_ports=[22], ...); associate_floating_ip -> ssh root@<ip> | H12: A1
... A29: P28 | B29: Pitfall trap | C29: H | D29: VALIDATE | E29: Convert my CHI@UC bare-metal script (add_node_reservation, node_type='compute_skylake', create_server) to run on CHI@Edge. | F29: Keeps node/flavor/server. | G29: Swap to device reservation (add_device_reservation/machine_type) + container.Container(image_ref, reservation_id).submit(); drop flavor/keypair/network; site CHI@Edge. | H29: A1

Sheet Artifacts
A1: Key | B1: Title | C1: Trovi link | D1: Backing GitHub repo (read in full) | E1: What it grounds
A2: A1 | B2: SSH on CHI@Edge | C2: https://trovi.chameleoncloud.org/dashboard/artifacts/4b08e80c-df0a-4866-bf29-19b5ad6a2950 | D2: https://github.com/ChameleonCloud/edge_ssh_image | E2: Setup, lease + device reservation, container launch, exposed port 22, public-key injection, FIP, exec, teardown, bare-metal→edge translation
A3: A2 | B3: Pi Camera Module 3 | C3: https://trovi.chameleoncloud.org/dashboard/artifacts/7d35f884-68d8-4b91-b42b-207717c9b742 | D3: https://github.com/ChameleonCloud/edge-picamera-image | E3: context.choose_site, hardware.get_devices() availability query, Lease + add_device_reservation(devices), Container device_profiles=['pi_libcamera'], capture still/video, download/upload
A4: A3 | B4: Sensors & GPIO (Sense HAT) | C4: https://trovi.chameleoncloud.org/dashboard/artifacts/1b8cdcba-e10c-4cae-8b1e-145037bc4cda | D4: https://github.com/ChameleonCloud/edge_sensehat_image | E4: Lease + add_device_reservation(device_name), Container device_profiles=['pi_sensehat'], read sensors via sense_hat, i2cdetect / GPIO, profile+image selection

Sheet Output
A1: ID | B1: Category | C1: Setup | D1: Model output (paste here) | E1: Screenshot file | F1: Score (0–2) | G1: Notes
A2: P01 | B2: Setup | C2: S1 · Chatbot (blind) | D2: To target CHI@Edge and select your project using python-chi, you can use the following minimal setup: import chi chi.use_site("CHI@Edge") chi.use_project("CHI-XXXXXX") # Replace with your project name This code imports the python-chi module, sets the site to CHI@Edge, and sets the active project. Replace "CHI-XXXXXX" with your actual project name. Alternatively, you can use interactive dropdown menus in a Jupyter Notebook: import chi chi.context.choose_site() chi.context.choose_project() Further Reading DocsJupyter Python Chi DocsGui | F2: 2 | G2: Gives both styles correctly; direct and concise. 'Further Reading' appended.
A3: P01 | B3: Setup | C3: S1 · Chatbot (artifact) | D3: To target CHI@Edge and select your project using python-chi, you can use the following minimal setup: import chi chi.use_site("CHI@Edge") chi.set("project_name", "Your_Project_Name") Replace "Your_Project_Name" with the actual name of your project. This will set up the python-chi library to use the CHI@Edge site and your specified project. Further Reading DocsGui BlogChi In A Box Update DocsFederation DocsGetting Started BlogSeamless Ssh Container Access With Chiedge BlogBack To School With Chameleon | F3: 2 | G3: Correct, matches artifact's exact style.
A4: P01 | B4: Setup | C4: S2 · GPT (blind) | D4: A minimal python-chi setup for CHI@Edge is: from chi import context # Select the CHI@Edge site context.use_site("CHI@Edge") # Select your project context.use_project("your-project-name") If you prefer using a project ID: from chi import context context.use_site("CHI@Edge") context.use_project("project-id") A slightly more complete example that verifies the active context: from chi import context context.use_site("CHI@Edge") context.use_project("your-project-name") print("Site:", context.site()) print("Project:", context.project()) Before running this, authenticate with your Chameleon credentials (typically via an application credential or sourced OpenStack RC file, depending on your environment). After use_site() and use_project(), subsequent python-chi operations will target CHI@Edge under the selected project. | F4: 1 | G4: Invents context.use_project() — looks plausible but not a real python-chi API.
A5: P01 | B5: Setup | C5: S2 · GPT (artifact) | D5: Based on the artifact, the minimal python-chi setup to target CHI@Edge and select your project is: import chi # Select the CHI@Edge site chi.use_site("CHI@Edge") # Select your project chi.set("project_name", "Chameleon") This is the exact setup used in the notebook before any lease or container operations: import chi chi.use_site("CHI@Edge") chi.set("project_name", "Chameleon") from chi import container from chi import lease The artifact explicitly uses: Site: chi.use_site("CHI@Edge") Project: chi.set("project_name", "Chameleon") After these two calls, you can proceed with lease creation (lease.create_lease) and container deployment (container.create_container) on CHI@Edge. | F5: 2 | G5: Verbatim from artifact; correct.
A6: P01 | B6: Setup | C6: S3 · Claude (blind) | D6: pythonimport chi chi.use_site("CHI@Edge") chi.set("project_name", "YOUR_PROJECT_NAME") # e.g. "CHI-XXXXXX" That's it — use_site points the client at the CHI@Edge API endpoint, and set("project_name", ...) selects which Chameleon project/allocation your subsequent calls (leases, containers, devices, etc.) run under. A couple of notes: Project name is usually the CHI-XXXXXX charge code shown on the Chameleon portal, not your username. You'll also need to be authenticated (e.g. via an application_credential set as OS_* env vars or chi.set("auth", {...})) before site/project selection actually does anything useful — let me know if you want that part too. | F6: 2 | G6: Correct + helpful note about auth credentials.
A7: P01 | B7: Setup | C7: S3 · Claude (artifact) | D7: Based on the artifact, the minimal python-chi setup to target CHI@Edge and select your project is: import chi # Select the CHI@Edge site chi.use_site("CHI@Edge") # Select your project chi.set("project_name", "Chameleon") This is the exact setup used in the notebook before any lease or container operations: import chi chi.use_site("CHI@Edge") chi.set("project_name", "Chameleon") from chi import container from chi import lease The artifact explicitly uses: Site: chi.use_site("CHI@Edge") Project: chi.set("project_name", "Chameleon") After these two calls, you can proceed with lease creation (lease.create_lease) and container deployment (container.create_container) on CHI@Edge. | F7: 2 | G7: Identical to GPT artifact; verbatim from artifact.
A8: P02 | B8: Reservation | C8: S1 · Chatbot (blind) | D8: To reserve one Raspberry Pi 4 on CHI@Edge for 2 hours, you can use the following Python code with the python-chi library: import chi # Create authentication context (most info automatically sourced from env) chi.use_site('CHI@Edge') # Define the lease parameters lease_name = "my-lease" node_type = "Raspberry Pi 4" # Ensure this is the correct node type for Raspberry Pi 4 node_count = 1 hours = 2 # Request a lease for nodes reservations = [] chi.lease.add_node_reservation(reservations, count=node_count, node_type=node_type) # Define the lease duration start_date, end_date = chi.lease.lease_duration(hours=hours) # Create the lease lease = chi.lease.create_lease(lease_name, reservations, start_date=start_date, end_date=end_date) # Wait for the lease to become active chi.lease.wait_for_active(lease.id) This code will create a lease for one Raspberry Pi 4 node on CHI@Edge for 2 hours. Please ensure that the node_type parameter is set to the correct value for Raspberry Pi 4 nodes on CHI@Edge. Also, note that you need to have the necessary credentials and environment variables set up to use the python-chi library. Further Reading BlogCloud Wrangling Chameleons Python Library | F8: 0 | G8: Falls into bare-metal trap: add_node_reservation + node_type.
A9: P02 | B9: Reservation | C9: S1 · Chatbot (artifact) | D9: o reserve one Raspberry Pi 4 on CHI@Edge for 2 hours, you can use the following Python code with the python-chi library: from chi import lease import os # Set the site chi.context.use_site("CHI@Edge") chi.context.choose_project() # Comment this line if running outside JupyterHub # machine name refers to the "type" of device machine_name = "raspberrypi4-64" # Reserving the specific device device_name = "iot-rpi4-picam3" # Replace with your desired device name # make a unique name for the lease username = os.environ.get("USER") lease_name = f"{username}-{device_name}" container_lease = lease.Lease(name=lease_name, duration=lease.timedelta(hours=2)) container_lease.add_device_reservation( amount=1, machine_type=machine_name, device_name=device_name ) container_lease.submit() print("Done!") Remember to replace "iot-rpi4-picam3" with your desired device name. Also, make sure you have the necessary permissions and that the device is available for reservation. After you're done with the reservation, don't forget to delete the lease to free up the device: # deleting the lease will free up the device now, instead of waiting for it to expire later container_lease.delete() Further Reading DocsGui BlogChi In A Box Update BlogExperiment Patterns Making Complex Experiments Easy BlogPackaging Your Experiments On Chameleon With Python Chi 10 BlogConducting Research On The Edge Chiedge DocsGetting Started | F9: 2 | G9: Correct API; over-pins to camera device from artifact; small typo.
A10: P02 | B10: Reservation | C10: S2 · GPT (blind) | D10: I cannot directly access CHI@Edge or make reservations on your behalf. To reserve a Raspberry Pi 4 on CHI@Edge: Log in to the CHI portal. Go to CHI@Edge resources. Open the Reservations interface. Select a Raspberry Pi 4 node. Set the reservation duration to 2 hours. Submit the reservation request. If you provide the reservation page details, available nodes, or any error message you're seeing, I can help you complete the process. | F10: 0 | G10: Refuses to write code; portal steps only.
A11: P02 | B11: Reservation | C11: S2 · GPT (artifact) | D11: To reserve one Raspberry Pi 4 on CHI@Edge for 2 hours, use the same lease workflow shown in the artifact, but set the lease duration to 2 hours instead of 4. The artifact uses machine_type="raspberrypi4-64" and creates a device reservation with amount=1. import chi from chi import lease import os # Authenticate chi.context.use_site("CHI@Edge") chi.context.choose_project() # Raspberry Pi 4 machine type machine_name = "raspberrypi4-64" # Choose a specific device device_name = "iot-rpi4-picam3" username = os.environ.get("USER") lease_name = f"{username}-{device_name}" # Reserve for 2 hours container_lease = lease.Lease( name=lease_name, duration=lease.timedelta(hours=2) ) container_lease.add_device_reservation( amount=1, machine_type=machine_name, device_name=device_name ) container_lease.submit() print("Lease created:", lease_name) The authentication method, machine type, and reservation API calls are taken directly from the CHI@Edge artifact. | F11: 2 | G11: Correct API; mirrors artifact closely.
A12: P02 | B12: Reservation | C12: S3 · Claude (blind) | D12: There's no MCP connector available for Chameleon Cloud / CHI@Edge. However, I can guide you through making the reservation yourself via the CHI@Edge web portal or the CLI. Reserving a Raspberry Pi 4 on CHI@Edge Option 1: Web Portal (Easiest) Log in at chi.edge.chameleoncloud.org with your Chameleon account. Go to Reservations → Leases in the left sidebar. Click + Create Lease and fill in: Lease name: anything you like (e.g. my-rpi4-test) Start time: now (or a specific time) End time: start + 2 hours Under Resources, click Add Resource: Resource type: Device Filter by device_type = rpi4 (or search for raspberry in the node filter) Set min/max count to 1 Click Create Lease and wait for it to move to ACTIVE status. Option 2: CLI with blazar (python-blazarclient) bash# Install if needed pip install python-blazarclient python-openstackclient # Source your CHI@Edge OpenRC file first source ~/chi-edge-openrc.sh # Create a 2-hour lease for 1 Raspberry Pi 4 openstack reservation lease create \ --reservation resource_type=device,resource_properties='["=","$device_type","rpi4"]',min=1,max=1 \ --start-date "$(date -u '+%Y-%m-%d %H:%M')" \ --end-date "$(date -u -d '+2 hours' '+%Y-%m-%d %H:%M')" \ my-rpi4-lease Note: On macOS, use gdate (from GNU coreutils) instead of date -d. After Your Lease is Active Once the lease shows ACTIVE, you can enroll the device and SSH into it via the CHI@Edge console or by using the assigned floating IP. Would you like help with any of the next steps — like launching a container on the reserved node? | F12: 0 | G12: Switches to openstack/Blazar CLI; no python-chi answer.
A13: P02 | B13: Reservation | C13: S3 · Claude (artifact) | D13: Here's the code to reserve a Raspberry Pi 4 on CHI@Edge for 2 hours, based on the artifact's patterns: pythonimport chi from chi import lease import os # Authenticate chi.context.use_site("CHI@Edge") chi.context.choose_project() # comment out if running outside JupyterHub # Device configuration machine_name = "raspberrypi4-64" device_name = "iot-rpi4-picam3" # change to "iot-rpi4-picam2" or "iot-rpi-cm4-02" if unavailable # Create a unique lease name username = os.environ.get("USER") lease_name = f"{username}-{device_name}" # Create and submit the lease for 2 hours container_lease = lease.Lease(name=lease_name, duration=lease.timedelta(hours=2)) container_lease.add_device_reservation( amount=1, machine_type=machine_name, device_name=device_name ) container_lease.submit() print("Done!") A few notes: machine_type is always "raspberrypi4-64" for RPi 4 devices on CHI@Edge — it refers to the device type, not a specific unit. device_name pins the reservation to a specific physical board. The artifact lists three options (iot-rpi4-picam3, iot-rpi4-picam2, iot-rpi-cm4-02); swap in whichever is available. Duration is changed to hours=2 from the artifact's default of 4. Once done, free the device early with container_lease.delete() rather than waiting for expiry. | F13: 2 | G13: Correct API; helpful notes on device alternatives.
... A67: P11 | B67: SSH / Dev | C67: S3 · Claude (artifact) | D67: Launching an SSH-enabled container on CHI@Edge Here's the complete workflow, based on the edge_ssh_image artifact. 1. Setup pythonimport chi from chi import container, lease chi.use_site("CHI@Edge") chi.set("project_name", "Chameleon") 2. Create a 1-day device lease This reserves two raspberrypi4-64 devices (only one will be used for the container): pythonmachine_name = "raspberrypi4-64" start, end = lease.lease_duration(days=1) lease_name = f"ssh-{machine_name}-{start}" reservations = [] lease.add_device_reservation(reservations, count=2, machine_name=machine_name) container_lease = lease.create_lease(lease_name, reservations) lease_id = container_lease["id"] print(f"Created lease {lease_name} ({lease_id}), waiting for it to become active…") lease.wait_for_active(lease_id) print("Lease is active!") 3. Launch the SSH container The image is a pre-built Ubuntu 22.04 with sshd configured for root login: pythoncontainer_name = f"tutorial-{machine_name}-ssh".replace("_", "-") try: my_container = container.create_container( container_name, image="ghcr.io/chameleoncloud/edge_ssh_image:latest", workdir="/home", exposed_ports=[22], reservation_id=lease.get_device_reservation(lease_id), platform_version=2, ) except RuntimeError as ex: print(ex) print(f"Stop/delete '{container_name}' and retry.") else: print(f"Container '{container_name}' created!") Image download can take several minutes the first time. 4. Inject your public key Before running this step, edit the file ./edge_user_public_key and replace its placeholder content with your actual one-line RSA public key (e.g. ssh-rsa AAAA…). python# Upload the key file into the container chi.container.upload(my_container.uuid, "./edge_user_public_key", "/root/.ssh/") # Set correct permissions on authorized_keys chi.container.execute(my_container.uuid, '/bin/bash -c "chmod 600 /root/.ssh/authorized_keys"') # Append your key to authorized_keys chi.container.execute(my_container.uuid, '/bin/bash -c "cat /root/.ssh/edge_user_public_key >> /root/.ssh/authorized_keys"') 5. Attach a floating IP and connect pythonip_address = chi.container.associate_floating_ip(my_container.uuid) print(f"ssh root@{ip_address}") Then on your local machine: bashssh root@<ip_address> If the connection hangs indefinitely, release the floating IP via the CHI@Edge OpenStack dashboard and re-run associate_floating_ip. 6. Cleanup when done pythonchi.container.destroy_container(my_container.uuid) How it all fits together WhatValueSiteCHI@EdgeDevice typeraspberrypi4-64 (×2 reserved, ×1 used)Container imageghcr.io/chameleoncloud/edge_ssh_image:latestExposed port22 (SSH)Loginroot + your RSA keyLease duration1 day The container image is Ubuntu 22.04 with PermitRootLogin yes and sshd -D as its entrypoint — no password needed, just your key pair. | F67: 2 | G67: Comprehensive correct workflow + summary table.
A68: P12 | B68: SSH / Dev | C68: S1 · Chatbot (blind)
A69: P12 | B69: SSH / Dev | C69: S1 · Chatbot (artifact)
A70: P12 | B70: SSH / Dev | C70: S2 · GPT (blind)
A71: P12 | B71: SSH / Dev | C71: S2 · GPT (artifact)
A72: P12 | B72: SSH / Dev | C72: S3 · Claude (blind)
A73: P12 | B73: SSH / Dev | C73: S3 · Claude (artifact)
A74: P13 | B74: SSH / Dev | C74: S1 · Chatbot (blind)
A75: P13 | B75: SSH / Dev | C75: S1 · Chatbot (artifact)
A76: P13 | B76: SSH / Dev | C76: S2 · GPT (blind)
A77: P13 | B77: SSH / Dev | C77: S2 · GPT (artifact)
A78: P13 | B78: SSH / Dev | C78: S3 · Claude (blind)
A79: P13 | B79: SSH / Dev | C79: S3 · Claude (artifact)
A80: P14 | B80: SSH / Dev | C80: S1 · Chatbot (blind) | D80: To get a Raspberry Pi on CHI@Edge that you can access with VS Code Remote-SSH, follow these steps: Create a CHI@Edge Site: First, ensure you have a CHI@Edge site set up. This involves registering your edge site and configuring it according to the CHI@Edge documentation. Provision a Raspberry Pi: Provision a Raspberry Pi at your edge site. This typically involves flashing the Pi with an appropriate operating system (like Raspberry Pi OS) and ensuring it has network connectivity. Install CHI@Edge Agent: Install the CHI@Edge agent on your Raspberry Pi. The agent allows your Pi to communicate with the CHI@Edge control plane, enabling you to manage it remotely. Configure SSH on the Raspberry Pi: Ensure SSH is enabled on your Raspberry Pi. This is usually enabled by default, but you may need to configure it to allow passwordless SSH login using keys. Generate SSH Keys: Generate a pair of SSH keys on your local machine if you haven't already. You'll need the public key to configure passwordless SSH login on your Raspberry Pi. Add SSH Key to Raspberry Pi: Copy the public SSH key to your Raspberry Pi (typically to the .ssh/authorized_keys file of the user you intend to log in as) to enable passwordless SSH login. Install VS Code and Remote-SSH Extension: On your local machine, install Visual Studio Code (VS Code) and the Remote-SSH extension. This extension allows you to connect to your Raspberry Pi remotely. Configure VS Code Remote-SSH: Configure the Remote-SSH extension in VS Code by adding a new SSH host that points to your Raspberry Pi's IP address or hostname. You'll need to specify the username you'll use to log in and the path to your private SSH key. Connect to Raspberry Pi with VS Code: Open VS Code, and using the Command Palette or the Remote Explorer, connect to your Raspberry Pi. Once connected, you can open folders, edit files, and use the terminal directly on your Raspberry Pi as if you were sitting in front of it. By following these steps, you should be able to set up a Raspberry Pi on CHI@Edge and access it using VS Code Remote-SSH for development and management purposes. | F80: 0 | G80: Treats it as a physical Pi setup (flashing OS); wrong context entirely.
A81: P14 | B81: SSH / Dev | C81: S1 · Chatbot (artifact) | D81: To get a Raspberry Pi on CHI@Edge that you can access with VS Code Remote-SSH, follow these steps based on the provided artifact and documentation: Select the CHI@Edge Site: Use the chi.use_site("CHI@Edge") function to select the CHI@Edge site. Set the Project Name: Set the project name to "Chameleon" using chi.set("project_name", "Chameleon"). Create a Lease: Create a 1-day lease for a Raspberry Pi 4 device. First, define the machine name as "raspberrypi4-64" and then use lease.lease_duration(days=1) to get the start and end dates for the lease. Create a unique lease name and add a device reservation for the Raspberry Pi 4 with count=2. Then, create the lease using lease.create_lease(lease_name, reservations). Wait for the Lease to Become Active: Use lease.wait_for_active(lease_id) to wait for the lease to become active. Create a Container: Create a container using the container.create_container function, specifying the container name, image as "ghcr.io/chameleoncloud/edge_ssh_image:latest", work directory as "/home", exposed ports as [22], and the reservation ID obtained from lease.get_device_reservation(lease_id). Also, specify platform_version=2. Upload Your Public Key: Upload your RSA public key to the container using chi.container.upload(my_container.uuid, "./edge_user_public_key", "/root/.ssh/"). Set Permissions and Append to Authorized Keys: Execute commands inside the container to set the permissions of the authorized keys file to 600 and append your public key to it using chi.container.execute. Associate a Floating IP: Associate a floating IP with the container using chi.container.associate_floating_ip(my_container.uuid) to get an IP address you can use to SSH into the container. SSH into the Container: Use the IP address obtained and the command ssh root@<ip_address> to connect to your Raspberry Pi on CHI@Edge. Destroy the Container: When you're done, destroy the container using chi.container.destroy_container(my_container.uuid) to free up resources. This process should give you a Raspberry Pi on CHI@Edge that you can access with VS Code Remote-SSH. Remember to replace the placeholder in the edge_user_public_key file with your actual RSA public key before uploading it. Further Reading DocsGui BlogChi In A Box Update DocsFederation DocsGetting Started BlogSeamless Ssh Container Access With Chiedge BlogBack To School With Chameleon | F81: 1 | G81: Right workflow in prose; misses VS Code config step; no code block.
A82: P14 | B82: SSH / Dev | C82: S2 · GPT (blind) | D82: Here’s the clean end-to-end path to get a Raspberry Pi running on CHI@Edge and accessible via VS Code Remote-SSH. 1. What you’re actually building You need 3 pieces: A Raspberry Pi (Edge node) CHI@Edge allocation (Kubernetes-backed edge slice) SSH entry path from your laptop → CHI gateway → Pi What this really means: your Pi must be reachable via a routable IP inside CHI@Edge or via a forwarded SSH service. 2. Prereqs (don’t skip this) Hardware Raspberry Pi 4/5 recommended Ethernet preferred (WiFi works but adds friction) Software on Pi Flash Raspberry Pi OS Lite (64-bit). During imaging: Enable SSH Set username/password or inject SSH key After boot: sudo apt update sudo apt install -y openssh-server Confirm: systemctl status ssh 3. Get access to CHI@Edge You need: CHI account (CHameleon cloud) Project allocation with CHI@Edge enabled Inside CHI dashboard: Go to CHI@Edge → Devices / Sites Reserve or register a node (your Pi or a gateway node depending on setup) Two common models: A. Direct Pi in edge network (best case) Pi is registered as an edge device Gets CHI-assigned IP or DHCP lease in edge subnet B. Pi behind a CHI gateway node (more common) You SSH into a CHI VM/gateway first Then hop to Pi over private edge network 4. Put Pi on CHI@Edge network Option A: DHCP (simplest) Plug Pi into CHI edge LAN. On Pi: ip a Look for assigned IP like: 10.x.x.x / 192.168.x.x (CHI internal range) Test gateway reachability: ping <chi-gateway-ip> Option B: Static IP (if required by CHI setup) Edit: sudo nano /etc/dhcpcd.conf Example: interface eth0 static ip_address=10.20.0.50/24 static routers=10.20.0.1 static domain_name_servers=8.8.8.8 Restart: sudo reboot 5. SSH access setup On Pi Make sure your key is installed: mkdir -p ~/.ssh nano ~/.ssh/authorized_keys Paste your laptop public key. Fix permissions: chmod 700 ~/.ssh chmod 600 ~/.ssh/authorized_keys From laptop test ssh pi@<pi-ip> If CHI requires jump host: ssh -J user@chi-gateway user@10.x.x.x 6. Make VS Code Remote-SSH work Install extension: Remote - SSH (Microsoft) Then configure: code ~/.ssh/config Add: Direct Pi Host chi-pi HostName 10.x.x.x User pi IdentityFile ~/.ssh/id_rsa Via CHI gateway Host chi-gateway HostName <gateway-public-ip> User <your-user> Host chi-pi HostName 10.x.x.x User pi ProxyJump chi-gateway Then connect: Ctrl+Shift+P Remote-SSH: Connect to Host Select chi-pi VS Code will install server-side components automatically. 7. Common CHI@Edge pitfalls No IP assigned Pi not on correct VLAN / port Edge switch port not activated in CHI portal SSH timeout Firewall blocking port 22 inside edge network Missing ProxyJump through CHI gateway VS Code fails but SSH works Usually shell startup issues Fix: echo 'exec bash' >> ~/.bashrc 8. Minimal sanity checklist Pi reachable via ping ssh pi@ip works locally CHI gateway reachable (if used) SSH key auth works (no password prompts) VS Code config uses correct HostName or ProxyJump If you want, next step is tighter automation: Terraform CHI@Edge + Pi provisioning pattern or k3s cluster with Pi as edge worker node or zero-trust SSH (tailscale/nebula overlay instead of CHI routing) Just say which direction. | F82: 0 | G82: Treats Pi as a LAN device; talks about DHCP and routers; wrong context.
A83: P14 | B83: SSH / Dev | C83: S2 · GPT (artifact) | D83: Goal: provision a CHI@Edge Raspberry Pi container and make it reachable via SSH in a way that VS Code Remote-SSH can use. What follows is the end-to-end sequence, aligned exactly with the CHI@Edge functional python-chi workflow from your artifact, with only the additions needed for VS Code compatibility (SSH key + stable IP + SSH config behavior). 1. Set site and project import chi from chi import lease, container chi.use_site("CHI@Edge") chi.set("project_name", "Chameleon") 2. Create a 1-day Raspberry Pi lease Key constraint from the artifact: raspberrypi4-64, count=2, no device profiles. machine_name = "raspberrypi4-64" start, end = lease.lease_duration(days=1) lease_name = f"vscode-ssh-{machine_name}-{start}" reservations = [] lease.add_device_reservation(reservations, count=2, machine_name=machine_name) container_lease = lease.create_lease(lease_name, reservations) lease_id = container_lease["id"] lease.wait_for_active(lease_id) At this point you have two reserved Pi devices. One will be bound to the container. 3. Start SSH-enabled container on the reserved Pi Important fields (from artifact): image: ghcr.io/chameleoncloud/edge_ssh_image:latest exposed_ports: [22] platform_version: 2 reservation_id from lease container_name = f"vscode-{machine_name}-ssh".replace("_", "-") my_container = container.create_container( container_name, image="ghcr.io/chameleoncloud/edge_ssh_image:latest", workdir="/home", exposed_ports=[22], reservation_id=lease.get_device_reservation(lease_id), platform_version=2, ) 4. Inject your SSH key (VS Code requirement) VS Code Remote-SSH requires a normal OpenSSH keypair. Create or reuse: ssh-keygen -t rsa -b 4096 -f ~/.ssh/chi_edge Then write the public key into: edge_user_public_key (one line, no newline breaks) Upload + install it: chi.container.upload(my_container.uuid, "./edge_user_public_key", "/root/.ssh/") chi.container.execute( my_container.uuid, '/bin/bash -c "chmod 600 /root/.ssh/authorized_keys"' ) chi.container.execute( my_container.uuid, '/bin/bash -c "cat /root/.ssh/edge_user_public_key >> /root/.ssh/authorized_keys"' ) 5. Attach floating IP (this is your VS Code target host) ip_address = chi.container.associate_floating_ip(my_container.uuid) print(ip_address) This IP is the only thing VS Code needs. 6. Test raw SSH first (mandatory sanity check) ssh -i ~/.ssh/chi_edge root@<IP> If this fails, VS Code will fail too. 7. VS Code Remote-SSH config Edit: ~/.ssh/config Add: Host chi-edge-pi HostName <IP> User root IdentityFile ~/.ssh/chi_edge StrictHostKeyChecking no UserKnownHostsFile /dev/null Then in VS Code: Command Palette → Remote-SSH: Connect to Host Select chi-edge-pi 8. Clean teardown (important on CHI@Edge) chi.container.destroy_container(my_container.uuid) Also release lease if your workflow requires explicit cleanup in your environment. What actually matters for VS Code success Only three things are critical: Container must expose port 22 (edge_ssh_image already does this) Public key must be correctly appended to /root/.ssh/authorized_keys Floating IP must be reachable from your local machine Everything else is orchestration. If you want, I can modify this into a single reusable function like provision_chi_edge_pi_for_vscode() that returns a ready SSH config block automatically. | F83: 2 | G83: Complete + adds VS Code ~/.ssh/config block.
A84: P14 | B84: SSH / Dev | C84: S3 · Claude (blind) | D84: Here's the full end-to-end walkthrough — from zero to VS Code connected to a Pi on CHI@Edge. Prerequisites Chameleon Cloud account at chameleoncloud.org with a project that has a CHI@Edge allocation python-chi and OpenStack CLI tools (or just the web GUI — covered below) Your SSH public key uploaded to the portal Step 1 — Upload your SSH key Go to chi.edge.chameleoncloud.org Project → Compute → Key Pairs → Import Public Key Paste your ~/.ssh/id_ed25519.pub (or RSA). Note the key name — you'll use it below. Step 2 — Reserve a Raspberry Pi node CHI@Edge uses Blazar for advance reservations. You must hold a lease before you can launch anything. Via the GUI (Experiment → Reservations → Leases → Create Lease): FieldValueLease namemy-pi-leaseStartnow (or scheduled)End+1 day (max varies by allocation)Resource typedeviceMachine name / filterraspberrypi4-64 (or leave blank to get any Pi)Min/Max count1 Hit Create and wait for status → ACTIVE (usually < 2 min). Via CLI (python-chi): pythonimport chi from chi import lease chi.use_site("CHI@Edge") chi.set("project_name", "YOUR_PROJECT") my_lease = lease.create_lease("my-pi-lease", reservations=[ lease.device_reservation(min=1, max=1, machine_name="raspberrypi4-64") ]) lease.wait_for_active(my_lease["id"]) print("Reservation ID:", lease.get_device_reservation(my_lease["id"])) Step 3 — Launch a container on the Pi CHI@Edge runs containers (Zun), not VMs. Pick an arm64 image with an SSH daemon. Via GUI (Experiment → Container → Containers → Create Container): FieldValueNamemy-piImageubuntu:22.04 (arm64 — Chameleon pulls the right arch)Reservationselect the lease you just createdExposed ports22Command(leave blank — we'll install sshd below) → After creation, open a Console session and run: bashapt-get update && apt-get install -y openssh-server mkdir -p /root/.ssh echo "YOUR_PUBLIC_KEY_HERE" >> /root/.ssh/authorized_keys chmod 700 /root/.ssh && chmod 600 /root/.ssh/authorized_keys service ssh start Via CLI: pythonfrom chi import container c = container.create_container( name="my-pi", image="ubuntu:22.04", exposed_ports=[22], reservation_id=RESERVATION_ID, # from step 2 platform_version=2, ) container.wait_for_active(c["uuid"]) Then exec into it to set up sshd as above. Step 4 — Attach a floating IP bash# Get the container's network port openstack port list --device-id <container-uuid> # Allocate a floating IP from the public pool openstack floating ip create public # Associate it openstack floating ip set --port <port-id> <floating-ip> Via GUI: Container detail page → Associate Floating IP → allocate from public pool. Note the floating IP — e.g. 192.5.87.42. Step 5 — Verify SSH access bashssh -i ~/.ssh/id_ed25519 root@192.5.87.42 If the firewall blocks you, add a security group rule: bashopenstack security group rule create default \ --protocol tcp --dst-port 22 --remote-ip 0.0.0.0/0 openstack server add security group <container-uuid> default Step 6 — Configure VS Code Remote-SSH Add this to your ~/.ssh/config: sshHost chameleon-pi HostName 192.5.87.42 # your floating IP User root IdentityFile ~/.ssh/id_ed25519 ServerAliveInterval 60 ServerAliveCountMax 3 Then in VS Code: Install the Remote - SSH extension (ms-vscode-remote.remote-ssh) Ctrl/Cmd + Shift + P → Remote-SSH: Connect to Host… Select chameleon-pi VS Code will install the Remote-SSH server on the Pi automatically — takes ~1 min on first connect You'll land in a full VS Code session running natively on the Pi's arm64 hardware. Tips & Gotchas IssueFixLease won't activateCheck your project's CHI@Edge allocation balance at the portalarm64 image failsSpecify arm64v8/ubuntu:22.04 explicitly if auto-detect failsVS Code server install failsThe Pi needs outbound internet; verify with curl https://update.code.visualstudio.com from the containerFloating IP quotaEach project gets a small quota; release unused IPs with openstack floating ip deleteLease expires mid-workRenew via Leases → Update Lease → extend end time before it expires — the container survives lease renewal Once you're connected, VS Code Remote-SSH gives you full IntelliSense, the integrated terminal, port forwarding, and extension support running directly on the Pi hardware. Let me know if you hit a snag at any step. | F84: 1 | G84: Surprisingly close — knows Blazar/Zun exist; some invented params.
A85: P14 | B85: SSH / Dev | C85: S3 · Claude (artifact) | D85: Here's the complete end-to-end setup, built directly from the artifact's API calls. 1. Prerequisites Local machine: Python env with python-chi installed (pip install python-chi) VS Code with the Remote - SSH extension An RSA key pair — if you don't have one: ssh-keygen -t rsa -b 4096 -f ~/.ssh/chi_edge 2. Prepare your public key file The artifact uploads a file called edge_user_public_key. Create it now: bashcp ~/.ssh/chi_edge.pub ./edge_user_public_key The placeholder in the artifact says replace this line with your RSA public key — this step is what replaces it. 3. Run the notebook / script pythonimport chi from chi import container, lease # ── Site & project ────────────────────────────────────────────────────────── chi.use_site("CHI@Edge") chi.set("project_name", "Chameleon") # change if your project name differs # ── Lease (1 day, 2× raspberrypi4-64) ─────────────────────────────────────── machine_name = "raspberrypi4-64" start, end = lease.lease_duration(days=1) lease_name = f"ssh-{machine_name}-{start}" reservations = [] lease.add_device_reservation(reservations, count=2, machine_name=machine_name) container_lease = lease.create_lease(lease_name, reservations) lease_id = container_lease["id"] print(f"Lease {lease_name} ({lease_id}) created — waiting for ACTIVE (up to 60 s)…") lease.wait_for_active(lease_id) print("Lease is active.") # ── Container ──────────────────────────────────────────────────────────────── container_name = f"tutorial-{machine_name}-ssh".replace("_", "-") try: my_container = container.create_container( container_name, image="ghcr.io/chameleoncloud/edge_ssh_image:latest", workdir="/home", exposed_ports=[22], reservation_id=lease.get_device_reservation(lease_id), platform_version=2, ) except RuntimeError as ex: print(ex) raise SystemExit(f"Stop/delete {container_name} then retry.") print(f"Container ready: {my_container.uuid}") # ── Inject your public key ─────────────────────────────────────────────────── chi.container.upload(my_container.uuid, "./edge_user_public_key", "/root/.ssh/") chi.container.execute(my_container.uuid, '/bin/bash -c "chmod 600 /root/.ssh/authorized_keys"') chi.container.execute(my_container.uuid, '/bin/bash -c "cat /root/.ssh/edge_user_public_key >> /root/.ssh/authorized_keys"') # ── Floating IP ────────────────────────────────────────────────────────────── ip = chi.container.associate_floating_ip(my_container.uuid) print(f"\n✅ ssh root@{ip}") print(f" (private key: ~/.ssh/chi_edge)") 4. Verify SSH works first bashssh -i ~/.ssh/chi_edge -o StrictHostKeyChecking=no root@<IP> If it hangs at "connecting to device", go to the CHI@Edge OpenStack dashboard, release the floating IP, and re-run only the associate_floating_ip cell. 5. Configure VS Code Remote-SSH Add this block to your ~/.ssh/config: Host chi-edge-pi HostName <IP from step 4> User root IdentityFile ~/.ssh/chi_edge ServerAliveInterval 60 ServerAliveCountMax 5 Then in VS Code: Ctrl/Cmd+Shift+P → Remote-SSH: Connect to Host… Pick chi-edge-pi VS Code will install its server-side agent on the Pi container and open a remote window — you can now open folders, use the terminal, run extensions, etc. 6. Cleanup (when done) pythonchi.container.destroy_container(my_container.uuid) Also let the lease expire or delete it via the dashboard to free the devices for others. Key facts from the artifact ThingValueDevice typeraspberrypi4-64 (reserved by machine_name, count=2)Device profilesnoneContainer imageghcr.io/chameleoncloud/edge_ssh_image:latestBase OSUbuntu 22.04 + openssh-server (sshd -D)Loginroot (PermitRootLogin enabled in image)Port22 | F85: 2 | G85: Complete end-to-end with VS Code config; cleanest of the three.
A86: P15 | B86: Peripherals · Camera | C86: S1 · Chatbot (blind)
A87: P15 | B87: Peripherals · Camera | C87: S1 · Chatbot (artifact)
A88: P15 | B88: Peripherals · Camera | C88: S2 · GPT (blind)
A89: P15 | B89: Peripherals · Camera | C89: S2 · GPT (artifact)
A90: P15 | B90: Peripherals · Camera | C90: S3 · Claude (blind)
A91: P15 | B91: Peripherals · Camera | C91: S3 · Claude (artifact)
A92: P16 | B92: Peripherals · Camera | C92: S1 · Chatbot (blind)
A93: P16 | B93: Peripherals · Camera | C93: S1 · Chatbot (artifact)
...

Sheet Summary
B2: Results summary
B3: Auto-computed from the Outputs sheet as you grade. Mean score (0–2) and % of max per setup.
B5: Model versions tested (fill in)
B6: S1 — Chatbot build / date:
B7: S2 — GPT model:
B8: S3 — Claude model + setting:
B11: Metric | C11: S1 · Chatbot (blind) | D11: S1 · Chatbot (artifact) | E11: S2 · GPT (blind) | F11: S2 · GPT (artifact) | G11: S3 · Claude (blind) | H11: S3 · Claude (artifact)
B12: Mean score (0–2) | C12: =IFERROR(AVERAGEIF(Output!$C$2:$C$169,"S1 · Chatbot (blind)",Output!$F$2:$F$169),"—") -> 0.21428571 | D12: =IFERROR(AVERAGEIF(Output!$C$2:$C$169,"S1 · Chatbot (artifact)",Output!$F$2:$F$169),"—") -> 1.6428571 | E12: =IFERROR(AVERAGEIF(Output!$C$2:$C$169,"S2 · GPT (blind)",Output!$F$2:$F$169),"—") -> 0.14285714 | F12: =IFERROR(AVERAGEIF(Output!$C$2:$C$169,"S2 · GPT (artifact)",Output!$F$2:$F$169),"—") -> 2 | G12: =IFERROR(AVERAGEIF(Output!$C$2:$C$169,"S3 · Claude (blind)",Output!$F$2:$F$169),"—") -> 0.42857143 | H12: =IFERROR(AVERAGEIF(Output!$C$2:$C$169,"S3 · Claude (artifact)",Output!$F$2:$F$169),"—") -> 2
B13: % of max | C13: =IFERROR(AVERAGEIF(Output!$C$2:$C$169,"S1 · Chatbot (blind)",Output!$F$2:$F$169)/2*100,"—") -> 10.714286 | D13: =IFERROR(AVERAGEIF(Output!$C$2:$C$169,"S1 · Chatbot (artifact)",Output!$F$2:$F$169)/2*100,"—") -> 82.142857 | E13: =IFERROR(AVERAGEIF(Output!$C$2:$C$169,"S2 · GPT (blind)",Output!$F$2:$F$169)/2*100,"—") -> 7.1428571 | F13: =IFERROR(AVERAGEIF(Output!$C$2:$C$169,"S2 · GPT (artifact)",Output!$F$2:$F$169)/2*100,"—") -> 100 | G13: =IFERROR(AVERAGEIF(Output!$C$2:$C$169,"S3 · Claude (blind)",Output!$F$2:$F$169)/2*100,"—") -> 21.428571 | H13: =IFERROR(AVERAGEIF(Output!$C$2:$C$169,"S3 · Claude (artifact)",Output!$F$2:$F$169)/2*100,"—") -> 100
B14: Runs graded (of 28) | C14: =COUNTIFS(Output!$C$2:$C$169,"S1 · Chatbot (blind)",Output!$F$2:$F$169,"<>") -> 14 | D14: =COUNTIFS(Output!$C$2:$C$169,"S1 · Chatbot (artifact)",Output!$F$2:$F$169,"<>") -> 14 | E14: =COUNTIFS(Output!$C$2:$C$169,"S2 · GPT (blind)",Output!$F$2:$F$169,"<>") -> 14 | F14: =COUNTIFS(Output!$C$2:$C$169,"S2 · GPT (artifact)",Output!$F$2:$F$169,"<>") -> 14 | G14: =COUNTIFS(Output!$C$2:$C$169,"S3 · Claude (blind)",Output!$F$2:$F$169,"<>") -> 14 | H14: =COUNTIFS(Output!$C$2:$C$169,"S3 · Claude (artifact)",Output!$F$2:$F$169,"<>") -> 14
B16: Headline: blind → artifact lift
B17: Chatbot lift (pp) | C17: =IFERROR(AVERAGEIF(Output!$C$2:$C$169,"S1 · Chatbot (artifact)",Output!$F$2:$F$169)/2*100-AVERAGEIF(Output!$C$2:$C$169,"S1 · Chatbot (blind)",Output!$F$2:$F$169)/2*100,"—") -> 71.428571
B18: GPT lift (pp) | C18: =IFERROR(AVERAGEIF(Output!$C$2:$C$169,"S2 · GPT (artifact)",Output!$F$2:$F$169)/2*100-AVERAGEIF(Output!$C$2:$C$169,"S2 · GPT (blind)",Output!$F$2:$F$169)/2*100,"—") -> 92.857143
B19: Claude lift (pp) | C19: =IFERROR(AVERAGEIF(Output!$C$2:$C$169,"S3 · Claude (artifact)",Output!$F$2:$F$169)/2*100-AVERAGEIF(Output!$C$2:$C$169,"S3 · Claude (blind)",Output!$F$2:$F$169)/2*100,"—") -> 78.571429
B21: Mean score by category × setup
B22: Category | C22: S1 blind | D22: S1 art | E22: GPT blind | F22: GPT art | G22: Cla blind | H22: Cla art
B23: Setup | C23: =IFERROR(AVERAGEIFS(Output!$F$2:$F$169,Output!$C$2:$C$169,"S1 · Chatbot (blind)",Output!$B$2:$B$169,$B23),"—") -> 2 | D23: =IFERROR(AVERAGEIFS(Output!$F$2:$F$169,Output!$C$2:$C$169,"S1 · Chatbot (artifact)",Output!$B$2:$B$169,$B23),"—") -> 2 | E23: =IFERROR(AVERAGEIFS(Output!$F$2:$F$169,Output!$C$2:$C$169,"S2 · GPT (blind)",Output!$B$2:$B$169,$B23),"—") -> 1 | F23: =IFERROR(AVERAGEIFS(Output!$F$2:$F$169,Output!$C$2:$C$169,"S2 · GPT (artifact)",Output!$B$2:$B$169,$B23),"—") -> 2 | G23: =IFERROR(AVERAGEIFS(Output!$F$2:$F$169,Output!$C$2:$C$169,"S3 · Claude (blind)",Output!$B$2:$B$169,$B23),"—") -> 2 | H23: =IFERROR(AVERAGEIFS(Output!$F$2:$F$169,Output!$C$2:$C$169,"S3 · Claude (artifact)",Output!$B$2:$B$169,$B23),"—") -> 2
B24: Reservation | C24: =IFERROR(AVERAGEIFS(Output!$F$2:$F$169,Output!$C$2:$C$169,"S1 · Chatbot (blind)",Output!$B$2:$B$169,$B24),"—") -> 0 | D24: =IFERROR(AVERAGEIFS(Output!$F$2:$F$169,Output!$C$2:$C$169,"S1 · Chatbot (artifact)",Output!$B$2:$B$169,$B24),"—") -> 1.6666667 | E24: =IFERROR(AVERAGEIFS(Output!$F$2:$F$169,Output!$C$2:$C$169,"S2 · GPT (blind)",Output!$B$2:$B$169,$B24),"—") -> 0 | F24: =IFERROR(AVERAGEIFS(Output!$F$2:$F$169,Output!$C$2:$C$169,"S2 · GPT (artifact)",Output!$B$2:$B$169,$B24),"—") -> 2 | G24: =IFERROR(AVERAGEIFS(Output!$F$2:$F$169,Output!$C$2:$C$169,"S3 · Claude (blind)",Output!$B$2:$B$169,$B24),"—") -> 0 | H24: =IFERROR(AVERAGEIFS(Output!$F$2:$F$169,Output!$C$2:$C$169,"S3 · Claude (artifact)",Output!$B$2:$B$169,$B24),"—") -> 2
B25: Container | C25: =IFERROR(AVERAGEIFS(Output!$F$2:$F$169,Output!$C$2:$C$169,"S1 · Chatbot (blind)",Output!$B$2:$B$169,$B25),"—") -> 0.16666667 | D25: =IFERROR(AVERAGEIFS(Output!$F$2:$F$169,Output!$C$2:$C$169,"S1 · Chatbot (artifact)",Output!$B$2:$B$169,$B25),"—") -> 1.8333333 | E25: =IFERROR(AVERAGEIFS(Output!$F$2:$F$169,Output!$C$2:$C$169,"S2 · GPT (blind)",Output!$B$2:$B$169,$B25),"—") -> 0.16666667 | F25: =IFERROR(AVERAGEIFS(Output!$F$2:$F$169,Output!$C$2:$C$169,"S2 · GPT (artifact)",Output!$B$2:$B$169,$B25),"—") -> 2 | G25: =IFERROR(AVERAGEIFS(Output!$F$2:$F$169,Output!$C$2:$C$169,"S3 · Claude (blind)",Output!$B$2:$B$169,$B25),"—") -> 0.33333333 | H25: =IFERROR(AVERAGEIFS(Output!$F$2:$F$169,Output!$C$2:$C$169,"S3 · Claude (artifact)",Output!$B$2:$B$169,$B25),"—") -> 2
B26: SSH / Dev | C26: =IFERROR(AVERAGEIFS(Output!$F$2:$F$169,Output!$C$2:$C$169,"S1 · Chatbot (blind)",Output!$B$2:$B$169,$B26),"—") -> 0 | D26: =IFERROR(AVERAGEIFS(Output!$F$2:$F$169,Output!$C$2:$C$169,"S1 · Chatbot (artifact)",Output!$B$2:$B$169,$B26),"—") -> 1 | E26: =IFERROR(AVERAGEIFS(Output!$F$2:$F$169,Output!$C$2:$C$169,"S2 · GPT (blind)",Output!$B$2:$B$169,$B26),"—") -> 0 | F26: =IFERROR(AVERAGEIFS(Output!$F$2:$F$169,Output!$C$2:$C$169,"S2 · GPT (artifact)",Output!$B$2:$B$169,$B26),"—") -> 2 | G26: =IFERROR(AVERAGEIFS(Output!$F$2:$F$169,Output!$C$2:$C$169,"S3 · Claude (blind)",Output!$B$2:$B$169,$B26),"—") -> 0.5 | H26: =IFERROR(AVERAGEIFS(Output!$F$2:$F$169,Output!$C$2:$C$169,"S3 · Claude (artifact)",Output!$B$2:$B$169,$B26),"—") -> 2
B27: Peripherals · Camera | C27: =IFERROR(AVERAGEIFS(Output!$F$2:$F$169,Output!$C$2:$C$169,"S1 · Chatbot (blind)",Output!$B$2:$B$169,$B27),"—") -> — | D27: =IFERROR(AVERAGEIFS(Output!$F$2:$F$169,Output!$C$2:$C$169,"S1 · Chatbot (artifact)",Output!$B$2:$B$169,$B27),"—") -> — | E27: =IFERROR(AVERAGEIFS(Output!$F$2:$F$169,Output!$C$2:$C$169,"S2 · GPT (blind)",Output!$B$2:$B$169,$B27),"—") -> — | F27: =IFERROR(AVERAGEIFS(Output!$F$2:$F$169,Output!$C$2:$C$169,"S2 · GPT (artifact)",Output!$B$2:$B$169,$B27),"—") -> — | G27: =IFERROR(AVERAGEIFS(Output!$F$2:$F$169,Output!$C$2:$C$169,"S3 · Claude (blind)",Output!$B$2:$B$169,$B27),"—") -> — | H27: =IFERROR(AVERAGEIFS(Output!$F$2:$F$169,Output!$C$2:$C$169,"S3 · Claude (artifact)",Output!$B$2:$B$169,$B27),"—") -> —
B28: Peripherals · Sense HAT | C28: =IFERROR(AVERAGEIFS(Output!$F$2:$F$169,Output!$C$2:$C$169,"S1 · Chatbot (blind)",Output!$B$2:$B$169,$B28),"—") -> — | D28: =IFERROR(AVERAGEIFS(Output!$F$2:$F$169,Output!$C$2:$C$169,"S1 · Chatbot (artifact)",Output!$B$2:$B$169,$B28),"—") -> — | E28: =IFERROR(AVERAGEIFS(Output!$F$2:$F$169,Output!$C$2:$C$169,"S2 · GPT (blind)",Output!$B$2:$B$169,$B28),"—") -> — | F28: =IFERROR(AVERAGEIFS(Output!$F$2:$F$169,Output!$C$2:$C$169,"S2 · GPT (artifact)",Output!$B$2:$B$169,$B28),"—") -> — | G28: =IFERROR(AVERAGEIFS(Output!$F$2:$F$169,Output!$C$2:$C$169,"S3 · Claude (blind)",Output!$B$2:$B$169,$B28),"—") -> — | H28: =IFERROR(AVERAGEIFS(Output!$F$2:$F$169,Output!$C$2:$C$169,"S3 · Claude (artifact)",Output!$B$2:$B$169,$B28),"—") -> —
B29: Availability | C29: =IFERROR(AVERAGEIFS(Output!$F$2:$F$169,Output!$C$2:$C$169,"S1 · Chatbot (blind)",Output!$B$2:$B$169,$B29),"—") -> 0 | D29: =IFERROR(AVERAGEIFS(Output!$F$2:$F$169,Output!$C$2:$C$169,"S1 · Chatbot (artifact)",Output!$B$2:$B$169,$B29),"—") -> 1 | E29: =IFERROR(AVERAGEIFS(Output!$F$2:$F$169,Output!$C$2:$C$169,"S2 · GPT (blind)",Output!$B$2:$B$169,$B29),"—") -> 0 | F29: =IFERROR(AVERAGEIFS(Output!$F$2:$F$169,Output!$C$2:$C$169,"S2 · GPT (artifact)",Output!$B$2:$B$169,$B29),"—") -> 2 | G29: =IFERROR(AVERAGEIFS(Output!$F$2:$F$169,Output!$C$2:$C$169,"S3 · Claude (blind)",Output!$B$2:$B$169,$B29),"—") -> 0 | H29: =IFERROR(AVERAGEIFS(Output!$F$2:$F$169,Output!$C$2:$C$169,"S3 · Claude (artifact)",Output!$B$2:$B$169,$B29),"—") -> 2
B30: Pitfall trap | C30: =IFERROR(AVERAGEIFS(Output!$F$2:$F$169,Output!$C$2:$C$169,"S1 · Chatbot (blind)",Output!$B$2:$B$169,$B30),"—") -> 0 | D30: =IFERROR(AVERAGEIFS(Output!$F$2:$F$169,Output!$C$2:$C$169,"S1 · Chatbot (artifact)",Output!$B$2:$B$169,$B30),"—") -> 2 | E30: =IFERROR(AVERAGEIFS(Output!$F$2:$F$169,Output!$C$2:$C$169,"S2 · GPT (blind)",Output!$B$2:$B$169,$B30),"—") -> 0 | F30: =IFERROR(AVERAGEIFS(Output!$F$2:$F$169,Output!$C$2:$C$169,"S2 · GPT (artifact)",Output!$B$2:$B$169,$B30),"—") -> 2 | G30: =IFERROR(AVERAGEIFS(Output!$F$2:$F$169,Output!$C$2:$C$169,"S3 · Claude (blind)",Output!$B$2:$B$169,$B30),"—") -> 1 | H30: =IFERROR(AVERAGEIFS(Output!$F$2:$F$169,Output!$C$2:$C$169,"S3 · Claude (artifact)",Output!$B$2:$B$169,$B30),"—") -> 2
